Workbook

Sheet Bas
A1: ƏSAS VƏSAİTLƏR VƏ QMA — Amortizasiya Uçotu | VM AZ 114, 115
A3: Şirkətin adı:
A4: İl: | B4: 2025
A5: Sahibkar kateqoriyası: | B5: Mikro
A7: KATEQORİYA ÜZRƏ YEKUN
A8: Kateqoriya | B8: Qalıq (il əvvəli) | C8: Amortizasiya | D8: Qalıq (il sonu) | E8: Təmir fondu | F8: Növbəti il limiti
A9: Binalar, tikililər | B9: =IFERROR(SUMIF(EV!B:B,"bt",EV!G:G),0) -> 38447.54 | C9: =IFERROR(SUMIF(EV!B:B,"bt",EV!Q:Q),0) -> 0 | D9: =IFERROR(SUMIF(EV!B:B,"bt",EV!W:W),0) -> 38447.54 | E9: =IFERROR(SUMIF('Təmir Fondu'!A:A,"bt",'Təmir Fondu'!G:G),0) -> 0 | F9: =IFERROR(SUMIF(EV!B:B,"bt",EV!W:W)*0.02,0) -> 768.9508
A10: Maşınlar, avadanlıq | B10: =IFERROR(SUMIF(EV!B:B,"ma",EV!G:G),0) -> 0 | C10: =IFERROR(SUMIF(EV!B:B,"ma",EV!Q:Q),0) -> 0 | D10: =IFERROR(SUMIF(EV!B:B,"ma",EV!W:W),0) -> 0 | E10: =IFERROR(SUMIF('Təmir Fondu'!A:A,"ma",'Təmir Fondu'!G:G),0) -> 0 | F10: =IFERROR(SUMIF(EV!B:B,"ma",EV!W:W)*0.05,0) -> 0
A11: Nəqliyyat vasitələri | B11: =IFERROR(SUMIF(EV!B:B,"nv",EV!G:G),0) -> 0 | C11: =IFERROR(SUMIF(EV!B:B,"nv",EV!Q:Q),0) -> 0 | D11: =IFERROR(SUMIF(EV!B:B,"nv",EV!W:W),0) -> 0 | E11: =IFERROR(SUMIF('Təmir Fondu'!A:A,"nv",'Təmir Fondu'!G:G),0) -> 0 | F11: =IFERROR(SUMIF(EV!B:B,"nv",EV!W:W)*0.03,0) -> 0
A12: Yük maşınları | B12: =IFERROR(SUMIF(EV!B:B,"ym",EV!G:G),0) -> 0 | C12: =IFERROR(SUMIF(EV!B:B,"ym",EV!Q:Q),0) -> 0 | D12: =IFERROR(SUMIF(EV!B:B,"ym",EV!W:W),0) -> 0 | E12: =IFERROR(SUMIF('Təmir Fondu'!A:A,"ym",'Təmir Fondu'!G:G),0) -> 0 | F12: =IFERROR(SUMIF(EV!B:B,"ym",EV!W:W)*0.08,0) -> 0
A13: Yüksək texnologiya | B13: =IFERROR(SUMIF(EV!B:B,"yt",EV!G:G),0) -> 70972.117 | C13: =IFERROR(SUMIF(EV!B:B,"yt",EV!Q:Q),0) -> 0 | D13: =IFERROR(SUMIF(EV!B:B,"yt",EV!W:W),0) -> 70972.117 | E13: =IFERROR(SUMIF('Təmir Fondu'!A:A,"yt",'Təmir Fondu'!G:G),0) -> 0 | F13: =IFERROR(SUMIF(EV!B:B,"yt",EV!W:W)*0.03,0) -> 2129.1635
A14: Digər əsas vəsaitlər | B14: =IFERROR(SUMIF(EV!B:B,"dg",EV!G:G),0) -> 11260.879 | C14: =IFERROR(SUMIF(EV!B:B,"dg",EV!Q:Q),0) -> 0 | D14: =IFERROR(SUMIF(EV!B:B,"dg",EV!W:W),0) -> 11260.879 | E14: =IFERROR(SUMIF('Təmir Fondu'!A:A,"dg",'Təmir Fondu'!G:G),0) -> 0 | F14: =IFERROR(SUMIF(EV!B:B,"dg",EV!W:W)*0.03,0) -> 337.82638
A15: İcarə ƏV-nin təmiri | B15: =IFERROR(SUMIF(EV!B:B,"it",EV!G:G),0) -> 0 | C15: =IFERROR(SUMIF(EV!B:B,"it",EV!Q:Q),0) -> 0 | D15: =IFERROR(SUMIF(EV!B:B,"it",EV!W:W),0) -> 0 | E15: =IFERROR(SUMIF('Təmir Fondu'!A:A,"it",'Təmir Fondu'!G:G),0) -> 0 | F15: =IFERROR(SUMIF(EV!B:B,"it",EV!W:W)*0.03,0) -> 0
A16: QMA — FİM məlum | B16: =IFERROR(SUMIF(QMA!A:A,"qma-m",QMA!D:D),0) -> 0 | C16: =IFERROR(SUMIF(QMA!A:A,"qma-m",QMA!J:J),0) -> 0 | D16: =IFERROR(SUMIF(QMA!A:A,"qma-m",QMA!N:N),0) -> 0 | E16: "" | F16: ""
A17: QMA — FİM nəməlum | B17: =IFERROR(SUMIF(QMA!A:A,"qma-n",QMA!D:D),0) -> 4384.59 | C17: =IFERROR(SUMIF(QMA!A:A,"qma-n",QMA!J:J),0) -> 438.459 | D17: =IFERROR(SUMIF(QMA!A:A,"qma-n",QMA!N:N),0) -> 3498.597 | E17: "" | F17: ""
A18: C Ə M İ | B18: =SUM(B9:B17) -> 125065.13 | C18: =SUM(C9:C17) -> 438.459 | D18: =SUM(D9:D17) -> 124179.13 | E18: =SUM(E9:E17) -> 0
A20: Sarı = daxil edin | Boz = formula, toxunmayın | ⚠ = diqqət tələb edir

Sheet EV
A1: ƏSAS VƏSAİTLƏR — Amortizasiya Cədvəli | VM AZ Maddə 114
A2: İdentifikasiya | G2: İlin əvvəlinə | J2: Daxilolmalar | N2: Xaricetmə | Q2: Amortizasiya | V2: İlin sonuna
A3: ⚠ | B3: Kod | C3: İnv.№ | D3: Adı | E3: Kontragent | F3: Alış tarixi | G3: Qalıq dəyər (il əvvəli) | H3: İlkin dəyər (il əvvəli) | I3: Yığılmış (il əvvəli) | J3: Daxilolma İlkin dəyər | K3: Faktiki təmir | L3: Gəlirdən çıxılan | M3: Kapital- laşan | N3: Xaric İlkin | O3: Xaric Yığılmış | P3: Xaric Qalıq | Q3: Hesab. Amort. | R3: Amort. Baza | S3: Amort. Dərəcə | V3: İlkin dəyər (il sonu) | W3: Qalıq dəyər (il sonu) | X3: Yığılmış (il sonu)
B4: C Ə M İ | G4: =IFERROR(SUM(G6:G505),0) -> 120680.54 | H4: =IFERROR(SUM(H6:H505),0) -> 190908.16 | I4: =IFERROR(SUM(I6:I505),0) -> 70227.624 | J4: =IFERROR(SUM(J6:J505),0) -> 0 | K4: =IFERROR(SUM(K6:K505),0) -> 0 | L4: =IFERROR(SUM(L6:L505),0) -> 0 | Q4: =IFERROR(SUM(Q6:Q505),0) -> 0 | V4: =IFERROR(SUM(V6:V505),0) -> 190908.16 | W4: =IFERROR(SUM(W6:W505),0) -> 120680.54 | X4: =IFERROR(SUM(X6:X505),0) -> 70227.624
A6: =IF(AND(B6<>"",G6>0,OR(G6<500,G6<Y6*0.05)),"⚠","") | B6: bt | D6: Binalar, tikililər | G6: 19223.77 | H6: 21981.36 | I6: 2757.59 | M6: =IF(OR(K6="",K6=0),"",IFERROR(MAX(0,K6-L6),0)) | P6: =IF(N6="","",IFERROR(N6-O6,0)) | Q6: =IF(B6="","",IFERROR(IF(U6<>"",U6,IF(T6=1,G6+IFERROR(J6,0)+IFERROR(M6,0)-IFERROR(P6,0),(G6+IFERROR(J6,0)+IFERROR(M6,0)-IFERROR(P6,0))*S6)),0)) -> 0 | R6: =IF(B6="","",IFERROR(G6+IFERROR(J6,0)+IFERROR(M6,0)-IFERROR(P6,0),0)) -> 0 | S6: 0 | V6: =IF(B6="","",IFERROR(H6+IFERROR(J6,0)-IFERROR(N6,0),0)) -> 21981.36 | W6: =IF(B6="","",IFERROR(V6-X6,0)) -> 19223.77 | X6: =IF(B6="","",IFERROR(I6+Q6-IFERROR(O6,0),0)) -> 2757.59 | Y6: 21981.36
A7: =IF(AND(B7<>"",G7>0,OR(G7<500,G7<Y7*0.05)),"⚠","") | B7: ma | D7: Maşınlar, avadanlıq | M7: =IF(OR(K7="",K7=0),"",IFERROR(MAX(0,K7-L7),0)) | P7: =IF(N7="","",IFERROR(N7-O7,0)) | Q7: =IF(B7="","",IFERROR(IF(U7<>"",U7,IF(T7=1,G7+IFERROR(J7,0)+IFERROR(M7,0)-IFERROR(P7,0),(G7+IFERROR(J7,0)+IFERROR(M7,0)-IFERROR(P7,0))*S7)),0)) -> 0 | R7: =IF(B7="","",IFERROR(G7+IFERROR(J7,0)+IFERROR(M7,0)-IFERROR(P7,0),0)) -> 0 | S7: 0 | V7: =IF(B7="","",IFERROR(H7+IFERROR(J7,0)-IFERROR(N7,0),0)) -> 0 | W7: =IF(B7="","",IFERROR(V7-X7,0)) -> 0 | X7: =IF(B7="","",IFERROR(I7+Q7-IFERROR(O7,0),0)) -> 0 | Y7: 0
A8: =IF(AND(B8<>"",G8>0,OR(G8<500,G8<Y8*0.05)),"⚠","") | B8: nv | D8: Nəqliyyat vasitələri | M8: =IF(OR(K8="",K8=0),"",IFERROR(MAX(0,K8-L8),0)) | P8: =IF(N8="","",IFERROR(N8-O8,0)) | Q8: =IF(B8="","",IFERROR(IF(U8<>"",U8,IF(T8=1,G8+IFERROR(J8,0)+IFERROR(M8,0)-IFERROR(P8,0),(G8+IFERROR(J8,0)+IFERROR(M8,0)-IFERROR(P8,0))*S8)),0)) -> 0 | R8: =IF(B8="","",IFERROR(G8+IFERROR(J8,0)+IFERROR(M8,0)-IFERROR(P8,0),0)) -> 0 | S8: 0 | V8: =IF(B8="","",IFERROR(H8+IFERROR(J8,0)-IFERROR(N8,0),0)) -> 0 | W8: =IF(B8="","",IFERROR(V8-X8,0)) -> 0 | X8: =IF(B8="","",IFERROR(I8+Q8-IFERROR(O8,0),0)) -> 0 | Y8: 0
A9: =IF(AND(B9<>"",G9>0,OR(G9<500,G9<Y9*0.05)),"⚠","") | B9: ym | D9: Yük maşınları | M9: =IF(OR(K9="",K9=0),"",IFERROR(MAX(0,K9-L9),0)) | P9: =IF(N9="","",IFERROR(N9-O9,0)) | Q9: =IF(B9="","",IFERROR(IF(U9<>"",U9,IF(T9=1,G9+IFERROR(J9,0)+IFERROR(M9,0)-IFERROR(P9,0),(G9+IFERROR(J9,0)+IFERROR(M9,0)-IFERROR(P9,0))*S9)),0)) -> 0 | R9: =IF(B9="","",IFERROR(G9+IFERROR(J9,0)+IFERROR(M9,0)-IFERROR(P9,0),0)) -> 0 | S9: 0 | V9: =IF(B9="","",IFERROR(H9+IFERROR(J9,0)-IFERROR(N9,0),0)) -> 0 | W9: =IF(B9="","",IFERROR(V9-X9,0)) -> 0 | X9: =IF(B9="","",IFERROR(I9+Q9-IFERROR(O9,0),0)) -> 0 | Y9: 0
A10: =IF(AND(B10<>"",G10>0,OR(G10<500,G10<Y10*0.05)),"⚠","") | B10: yt | D10: Yüksək texnologiya | G10: 35486.058 | H10: 57544.21 | I10: 22058.152 | M10: =IF(OR(K10="",K10=0),"",IFERROR(MAX(0,K10-L10),0)) | P10: =IF(N10="","",IFERROR(N10-O10,0)) | Q10: =IF(B10="","",IFERROR(IF(U10<>"",U10,IF(T10=1,G10+IFERROR(J10,0)+IFERROR(M10,0)-IFERROR(P10,0),(G10+IFERROR(J10,0)+IFERROR(M10,0)-IFERROR(P10,0))*S10)),0)) -> 0 | R10: =IF(B10="","",IFERROR(G10+IFERROR(J10,0)+IFERROR(M10,0)-IFERROR(P10,0),0)) -> 0 | S10: 0 | V10: =IF(B10="","",IFERROR(H10+IFERROR(J10,0)-IFERROR(N10,0),0)) -> 57544.21 | W10: =IF(B10="","",IFERROR(V10-X10,0)) -> 35486.058 | X10: =IF(B10="","",IFERROR(I10+Q10-IFERROR(O10,0),0)) -> 22058.152 | Y10: 57544.21
A11: =IF(AND(B11<>"",G11>0,OR(G11<500,G11<Y11*0.05)),"⚠","") | B11: dg | D11: Digər əsas vəsaitlər | G11: 5630.4396 | H11: 15928.51 | I11: 10298.07 | M11: =IF(OR(K11="",K11=0),"",IFERROR(MAX(0,K11-L11),0)) | P11: =IF(N11="","",IFERROR(N11-O11,0)) | Q11: =IF(B11="","",IFERROR(IF(U11<>"",U11,IF(T11=1,G11+IFERROR(J11,0)+IFERROR(M11,0)-IFERROR(P11,0),(G11+IFERROR(J11,0)+IFERROR(M11,0)-IFERROR(P11,0))*S11)),0)) -> 0 | R11: =IF(B11="","",IFERROR(G11+IFERROR(J11,0)+IFERROR(M11,0)-IFERROR(P11,0),0)) -> 0 | S11: 0 | V11: =IF(B11="","",IFERROR(H11+IFERROR(J11,0)-IFERROR(N11,0),0)) -> 15928.51 | W11: =IF(B11="","",IFERROR(V11-X11,0)) -> 5630.4396 | X11: =IF(B11="","",IFERROR(I11+Q11-IFERROR(O11,0),0)) -> 10298.07 | Y11: 15928.51
A12: =IF(AND(B12<>"",G12>0,OR(G12<500,G12<Y12*0.05)),"⚠","") | B12: it | D12: İcarə ƏV-nin təmiri | M12: =IF(OR(K12="",K12=0),"",IFERROR(MAX(0,K12-L12),0)) | P12: =IF(N12="","",IFERROR(N12-O12,0)) | Q12: =IF(B12="","",IFERROR(IF(U12<>"",U12,IF(T12=1,G12+IFERROR(J12,0)+IFERROR(M12,0)-IFERROR(P12,0),(G12+IFERROR(J12,0)+IFERROR(M12,0)-IFERROR(P12,0))*S12)),0)) -> 0 | R12: =IF(B12="","",IFERROR(G12+IFERROR(J12,0)+IFERROR(M12,0)-IFERROR(P12,0),0)) -> 0 | S12: 0 | V12: =IF(B12="","",IFERROR(H12+IFERROR(J12,0)-IFERROR(N12,0),0)) -> 0 | W12: =IF(B12="","",IFERROR(V12-X12,0)) -> 0 | X12: =IF(B12="","",IFERROR(I12+Q12-IFERROR(O12,0),0)) -> 0 | Y12: 0
A13: =IF(AND(B13<>"",G13>0,OR(G13<500,G13<Y13*0.05)),"⚠","") | B13: bt | D13: Tamir | E13: "DEMİRÇİ DEVELOPMENT" MƏHDUD MƏSULİYYƏTLİ CƏMİYYƏTİ | F13: 44562 | G13: 8782.77 | H13: 10919 | I13: 2136.23 | M13: =IF(OR(K13="",K13=0),"",IFERROR(MAX(0,K13-L13),0)) | P13: =IF(N13="","",IFERROR(N13-O13,0)) | Q13: =IF(B13="","",IFERROR(IF(U13<>"",U13,IF(T13=1,G13+IFERROR(J13,0)+IFERROR(M13,0)-IFERROR(P13,0),(G13+IFERROR(J13,0)+IFERROR(M13,0)-IFERROR(P13,0))*S13)),0)) -> 0 | R13: =IF(B13="","",IFERROR(G13+IFERROR(J13,0)+IFERROR(M13,0)-IFERROR(P13,0),0)) -> 0 | S13: 0.07 | V13: =IF(B13="","",IFERROR(H13+IFERROR(J13,0)-IFERROR(N13,0),0)) -> 10919 | W13: =IF(B13="","",IFERROR(V13-X13,0)) -> 8782.77 | X13: =IF(B13="","",IFERROR(I13+Q13-IFERROR(O13,0),0)) -> 2136.23 | Y13: 10919
A14: =IF(AND(B14<>"",G14>0,OR(G14<500,G14<Y14*0.05)),"⚠","") | B14: dg | D14: Jalüz | E14: "DEMİRÇİ DEVELOPMENT" MƏHDUD MƏSULİYYƏTLİ CƏMİYYƏTİ | F14: 44562 | H14: 706 | I14: 706 | M14: =IF(OR(K14="",K14=0),"",IFERROR(MAX(0,K14-L14),0)) | P14: =IF(N14="","",IFERROR(N14-O14,0)) | Q14: =IF(B14="","",IFERROR(IF(U14<>"",U14,IF(T14=1,G14+IFERROR(J14,0)+IFERROR(M14,0)-IFERROR(P14,0),(G14+IFERROR(J14,0)+IFERROR(M14,0)-IFERROR(P14,0))*S14)),0)) -> 0 | R14: =IF(B14="","",IFERROR(G14+IFERROR(J14,0)+IFERROR(M14,0)-IFERROR(P14,0),0)) -> 0 | S14: 1 | T14: 1 | V14: =IF(B14="","",IFERROR(H14+IFERROR(J14,0)-IFERROR(N14,0),0)) -> 706 | W14: =IF(B14="","",IFERROR(V14-X14,0)) -> 0 | X14: =IF(B14="","",IFERROR(I14+Q14-IFERROR(O14,0),0)) -> 706 | Y14: 706
A15: =IF(AND(B15<>"",G15>0,OR(G15<500,G15<Y15*0.05)),"⚠","") | B15: dg | D15: BRK2651/Tur-K koltuk | E15: Zivella Mobiliya | F15: 44562 | H15: 689 | I15: 689 | M15: =IF(OR(K15="",K15=0),"",IFERROR(MAX(0,K15-L15),0)) | P15: =IF(N15="","",IFERROR(N15-O15,0)) | Q15: =IF(B15="","",IFERROR(IF(U15<>"",U15,IF(T15=1,G15+IFERROR(J15,0)+IFERROR(M15,0)-IFERROR(P15,0),(G15+IFERROR(J15,0)+IFERROR(M15,0)-IFERROR(P15,0))*S15)),0)) -> 0 | R15: =IF(B15="","",IFERROR(G15+IFERROR(J15,0)+IFERROR(M15,0)-IFERROR(P15,0),0)) -> 0 | S15: 1 | T15: 1 | V15: =IF(B15="","",IFERROR(H15+IFERROR(J15,0)-IFERROR(N15,0),0)) -> 689 | W15: =IF(B15="","",IFERROR(V15-X15,0)) -> 0 | X15: =IF(B15="","",IFERROR(I15+Q15-IFERROR(O15,0),0)) -> 689 | Y15: 689
A16: =IF(AND(B16<>"",G16>0,OR(G16<500,G16<Y16*0.05)),"⚠","") | B16: dg | D16: BRK2651/Tur-K koltuk | E16: Zivella Mobiliya | F16: 44562 | H16: 689 | I16: 689 | M16: =IF(OR(K16="",K16=0),"",IFERROR(MAX(0,K16-L16),0)) | P16: =IF(N16="","",IFERROR(N16-O16,0)) | Q16: =IF(B16="","",IFERROR(IF(U16<>"",U16,IF(T16=1,G16+IFERROR(J16,0)+IFERROR(M16,0)-IFERROR(P16,0),(G16+IFERROR(J16,0)+IFERROR(M16,0)-IFERROR(P16,0))*S16)),0)) -> 0 | R16: =IF(B16="","",IFERROR(G16+IFERROR(J16,0)+IFERROR(M16,0)-IFERROR(P16,0),0)) -> 0 | S16: 1 | T16: 1 | V16: =IF(B16="","",IFERROR(H16+IFERROR(J16,0)-IFERROR(N16,0),0)) -> 689 | W16: =IF(B16="","",IFERROR(V16-X16,0)) -> 0 | X16: =IF(B16="","",IFERROR(I16+Q16-IFERROR(O16,0),0)) -> 689 | Y16: 689
A17: =IF(AND(B17<>"",G17>0,OR(G17<500,G17<Y17*0.05)),"⚠","") | B17: dg | D17: BRK2651/Tur-K koltuk | E17: Zivella Mobiliya | F17: 44562 | H17: 689 | I17: 689 | M17: =IF(OR(K17="",K17=0),"",IFERROR(MAX(0,K17-L17),0)) | P17: =IF(N17="","",IFERROR(N17-O17,0)) | Q17: =IF(B17="","",IFERROR(IF(U17<>"",U17,IF(T17=1,G17+IFERROR(J17,0)+IFERROR(M17,0)-IFERROR(P17,0),(G17+IFERROR(J17,0)+IFERROR(M17,0)-IFERROR(P17,0))*S17)),0)) -> 0 | R17: =IF(B17="","",IFERROR(G17+IFERROR(J17,0)+IFERROR(M17,0)-IFERROR(P17,0),0)) -> 0 | S17: 1 | T17: 1 | V17: =IF(B17="","",IFERROR(H17+IFERROR(J17,0)-IFERROR(N17,0),0)) -> 689 | W17: =IF(B17="","",IFERROR(V17-X17,0)) -> 0 | X17: =IF(B17="","",IFERROR(I17+Q17-IFERROR(O17,0),0)) -> 689 | Y17: 689
A18: =IF(AND(B18<>"",G18>0,OR(G18<500,G18<Y18*0.05)),"⚠","") | B18: dg | D18: BRK2651/Tur-K koltuk | E18: Zivella Mobiliya | F18: 44562 | H18: 689 | I18: 689 | M18: =IF(OR(K18="",K18=0),"",IFERROR(MAX(0,K18-L18),0)) | P18: =IF(N18="","",IFERROR(N18-O18,0)) | Q18: =IF(B18="","",IFERROR(IF(U18<>"",U18,IF(T18=1,G18+IFERROR(J18,0)+IFERROR(M18,0)-IFERROR(P18,0),(G18+IFERROR(J18,0)+IFERROR(M18,0)-IFERROR(P18,0))*S18)),0)) -> 0 | R18: =IF(B18="","",IFERROR(G18+IFERROR(J18,0)+IFERROR(M18,0)-IFERROR(P18,0),0)) -> 0 | S18: 1 | T18: 1 | V18: =IF(B18="","",IFERROR(H18+IFERROR(J18,0)-IFERROR(N18,0),0)) -> 689 | W18: =IF(B18="","",IFERROR(V18-X18,0)) -> 0 | X18: =IF(B18="","",IFERROR(I18+Q18-IFERROR(O18,0),0)) -> 689 | Y18: 689
A19: =IF(AND(B19<>"",G19>0,OR(G19<500,G19<Y19*0.05)),"⚠","") | B19: dg | D19: BRK5215/Phase beşli sehpalı divan | E19: Zivella Mobiliya | F19: 44562 | G19: 1387.52 | H19: 2710 | I19: 1322.48 | M19: =IF(OR(K19="",K19=0),"",IFERROR(MAX(0,K19-L19),0)) | P19: =IF(N19="","",IFERROR(N19-O19,0)) | Q19: =IF(B19="","",IFERROR(IF(U19<>"",U19,IF(T19=1,G19+IFERROR(J19,0)+IFERROR(M19,0)-IFERROR(P19,0),(G19+IFERROR(J19,0)+IFERROR(M19,0)-IFERROR(P19,0))*S19)),0)) -> 0 | R19: =IF(B19="","",IFERROR(G19+IFERROR(J19,0)+IFERROR(M19,0)-IFERROR(P19,0),0)) -> 0 | S19: 0.2 | V19: =IF(B19="","",IFERROR(H19+IFERROR(J19,0)-IFERROR(N19,0),0)) -> 2710 | W19: =IF(B19="","",IFERROR(V19-X19,0)) -> 1387.52 | X19: =IF(B19="","",IFERROR(I19+Q19-IFERROR(O19,0),0)) -> 1322.48 | Y19: 2710
A20: =IF(AND(B20<>"",G20>0,OR(G20<500,G20<Y20*0.05)),"⚠","") | B20: dg | D20: OFİS BRANDİNG | E20: “ER-İNŞAAT SANAYİ TİCARƏT” MƏHDUD MƏSULİYYƏTLİ CƏMİYYƏTİ | F20: 44562 | H20: 680 | I20: 680 | M20: =IF(OR(K20="",K20=0),"",IFERROR(MAX(0,K20-L20),0)) | P20: =IF(N20="","",IFERROR(N20-O20,0)) | Q20: =IF(B20="","",IFERROR(IF(U20<>"",U20,IF(T20=1,G20+IFERROR(J20,0)+IFERROR(M20,0)-IFERROR(P20,0),(G20+IFERROR(J20,0)+IFERROR(M20,0)-IFERROR(P20,0))*S20)),0)) -> 0 | R20: =IF(B20="","",IFERROR(G20+IFERROR(J20,0)+IFERROR(M20,0)-IFERROR(P20,0),0)) -> 0 | S20: 0.2 | V20: =IF(B20="","",IFERROR(H20+IFERROR(J20,0)-IFERROR(N20,0),0)) -> 680 | W20: =IF(B20="","",IFERROR(V20-X20,0)) -> 0 | X20: =IF(B20="","",IFERROR(I20+Q20-IFERROR(O20,0),0)) -> 680 | Y20: 680
A21: =IF(AND(B21<>"",G21>0,OR(G21<500,G21<Y21*0.05)),"⚠","") | B21: dg | D21: X-name əsas masa yan tumbalı (2000x1660x760) (Liyon Valnut) | E21: "EMBAWOOD" MƏHDUD MƏSULİYYƏTLİ CƏMİYYƏTİ | F21: 44562 | G21: 660.48 | H21: 1290 | I21: 629.52 | M21: =IF(OR(K21="",K21=0),"",IFERROR(MAX(0,K21-L21),0)) | P21: =IF(N21="","",IFERROR(N21-O21,0)) | Q21: =IF(B21="","",IFERROR(IF(U21<>"",U21,IF(T21=1,G21+IFERROR(J21,0)+IFERROR(M21,0)-IFERROR(P21,0),(G21+IFERROR(J21,0)+IFERROR(M21,0)-IFERROR(P21,0))*S21)),0)) -> 0 | R21: =IF(B21="","",IFERROR(G21+IFERROR(J21,0)+IFERROR(M21,0)-IFERROR(P21,0),0)) -> 0 | S21: 0.2 | V21: =IF(B21="","",IFERROR(H21+IFERROR(J21,0)-IFERROR(N21,0),0)) -> 1290 | W21: =IF(B21="","",IFERROR(V21-X21,0)) -> 660.48 | X21: =IF(B21="","",IFERROR(I21+Q21-IFERROR(O21,0),0)) -> 629.52 | Y21: 1290
A22: =IF(AND(B22<>"",G22>0,OR(G22<500,G22<Y22*0.05)),"⚠","") | B22: dg | D22: Executive armchair - Glasgow - LA-862MH (Qara) | E22: "EMBAWOOD" MƏHDUD MƏSULİYYƏTLİ CƏMİYYƏTİ | F22: 44562 | H22: 600 | I22: 600 | M22: =IF(OR(K22="",K22=0),"",IFERROR(MAX(0,K22-L22),0)) | P22: =IF(N22="","",IFERROR(N22-O22,0)) | Q22: =IF(B22="","",IFERROR(IF(U22<>"",U22,IF(T22=1,G22+IFERROR(J22,0)+IFERROR(M22,0)-IFERROR(P22,0),(G22+IFERROR(J22,0)+IFERROR(M22,0)-IFERROR(P22,0))*S22)),0)) -> 0 | R22: =IF(B22="","",IFERROR(G22+IFERROR(J22,0)+IFERROR(M22,0)-IFERROR(P22,0),0)) -> 0 | S22: 1 | T22: 1 | V22: =IF(B22="","",IFERROR(H22+IFERROR(J22,0)-IFERROR(N22,0),0)) -> 600 | W22: =IF(B22="","",IFERROR(V22-X22,0)) -> 0 | X22: =IF(B22="","",IFERROR(I22+Q22-IFERROR(O22,0),0)) -> 600 | Y22: 600
A23: =IF(AND(B23<>"",G23>0,OR(G23<500,G23<Y23*0.05)),"⚠","") | B23: dg | D23: Toplantı masası (2400x1200) (Ag) | E23: "EMBAWOOD" MƏHDUD MƏSULİYYƏTLİ CƏMİYYƏTİ | F23: 44562 | G23: 508.42 | H23: 993 | I23: 484.58 | M23: =IF(OR(K23="",K23=0),"",IFERROR(MAX(0,K23-L23),0)) | P23: =IF(N23="","",IFERROR(N23-O23,0)) | Q23: =IF(B23="","",IFERROR(IF(U23<>"",U23,IF(T23=1,G23+IFERROR(J23,0)+IFERROR(M23,0)-IFERROR(P23,0),(G23+IFERROR(J23,0)+IFERROR(M23,0)-IFERROR(P23,0))*S23)),0)) -> 0 | R23: =IF(B23="","",IFERROR(G23+IFERROR(J23,0)+IFERROR(M23,0)-IFERROR(P23,0),0)) -> 0 | S23: 0.2 | V23: =IF(B23="","",IFERROR(H23+IFERROR(J23,0)-IFERROR(N23,0),0)) -> 993 | W23: =IF(B23="","",IFERROR(V23-X23,0)) -> 508.42 | X23: =IF(B23="","",IFERROR(I23+Q23-IFERROR(O23,0),0)) -> 484.58 | Y23: 993
A24: =IF(AND(B24<>"",G24>0,OR(G24<500,G24<Y24*0.05)),"⚠","") | B24: dg | D24: TV altı (Liyon Valnut, Qara) | E24: "EMBAWOOD" MƏHDUD MƏSULİYYƏTLİ CƏMİYYƏTİ | F24: 44562 | H24: 550 | I24: 550 | M24: =IF(OR(K24="",K24=0),"",IFERROR(MAX(0,K24-L24),0)) | P24: =IF(N24="","",IFERROR(N24-O24,0)) | Q24: =IF(B24="","",IFERROR(IF(U24<>"",U24,IF(T24=1,G24+IFERROR(J24,0)+IFERROR(M24,0)-IFERROR(P24,0),(G24+IFERROR(J24,0)+IFERROR(M24,0)-IFERROR(P24,0))*S24)),0)) -> 0 | R24: =IF(B24="","",IFERROR(G24+IFERROR(J24,0)+IFERROR(M24,0)-IFERROR(P24,0),0)) -> 0 | S24: 0.2 | V24: =IF(B24="","",IFERROR(H24+IFERROR(J24,0)-IFERROR(N24,0),0)) -> 550 | W24: =IF(B24="","",IFERROR(V24-X24,0)) -> 0 | X24: =IF(B24="","",IFERROR(I24+Q24-IFERROR(O24,0),0)) -> 550 | Y24: 550
A25: =IF(AND(B25<>"",G25>0,OR(G25<500,G25<Y25*0.05)),"⚠","") | B25: dg | D25: Dolab (1800x400x1400) | E25: "EMBAWOOD" MƏHDUD MƏSULİYYƏTLİ CƏMİYYƏTİ | F25: 44562 | H25: 757 | I25: 757 | M25: =IF(OR(K25="",K25=0),"",IFERROR(MAX(0,K25-L25),0)) | P25: =IF(N25="","",IFERROR(N25-O25,0)) | Q25: =IF(B25="","",IFERROR(IF(U25<>"",U25,IF(T25=1,G25+IFERROR(J25,0)+IFERROR(M25,0)-IFERROR(P25,0),(G25+IFERROR(J25,0)+IFERROR(M25,0)-IFERROR(P25,0))*S25)),0)) -> 0 | R25: =IF(B25="","",IFERROR(G25+IFERROR(J25,0)+IFERROR(M25,0)-IFERROR(P25,0),0)) -> 0 | S25: 0.2 | V25: =IF(B25="","",IFERROR(H25+IFERROR(J25,0)-IFERROR(N25,0),0)) -> 757 | W25: =IF(B25="","",IFERROR(V25-X25,0)) -> 0 | X25: =IF(B25="","",IFERROR(I25+Q25-IFERROR(O25,0),0)) -> 757 | Y25: 757
A26: =IF(AND(B26<>"",G26>0,OR(G26<500,G26<Y26*0.05)),"⚠","") | B26: yt | D26: Printer / Yazıcı | E26: "KOÇSİSTEM AZƏRBAYCAN" MƏHDUD MƏSULİYYƏTLİ CƏMİYYƏTİ | F26: 44562 | G26: 2992.1 | H26: 7092.4 | I26: 4100.3 | M26: =IF(OR(K26="",K26=0),"",IFERROR(MAX(0,K26-L26),0)) | P26: =IF(N26="","",IFERROR(N26-O26,0)) | Q26: =IF(B26="","",IFERROR(IF(U26<>"",U26,IF(T26=1,G26+IFERROR(J26,0)+IFERROR(M26,0)-IFERROR(P26,0),(G26+IFERROR(J26,0)+IFERROR(M26,0)-IFERROR(P26,0))*S26)),0)) -> 0 | R26: =IF(B26="","",IFERROR(G26+IFERROR(J26,0)+IFERROR(M26,0)-IFERROR(P26,0),0)) -> 0 | S26: 0.25 | V26: =IF(B26="","",IFERROR(H26+IFERROR(J26,0)-IFERROR(N26,0),0)) -> 7092.4 | W26: =IF(B26="","",IFERROR(V26-X26,0)) -> 2992.1 | X26: =IF(B26="","",IFERROR(I26+Q26-IFERROR(O26,0),0)) -> 4100.3 | Y26: 7092.4
A27: =IF(AND(B27<>"",G27>0,OR(G27<500,G27<Y27*0.05)),"⚠","") | B27: yt | D27: 75’’ TV TV LED GR 75 VLX 7860 | E27: "SOLİTON LTD" MƏHDUD MƏSULİYYƏTLİ CƏMİYYƏTİ | F27: 44562 | G27: 1132.27 | H27: 2683.9 | I27: 1551.63 | M27: =IF(OR(K27="",K27=0),"",IFERROR(MAX(0,K27-L27),0)) | P27: =IF(N27="","",IFERROR(N27-O27,0)) | Q27: =IF(B27="","",IFERROR(IF(U27<>"",U27,IF(T27=1,G27+IFERROR(J27,0)+IFERROR(M27,0)-IFERROR(P27,0),(G27+IFERROR(J27,0)+IFERROR(M27,0)-IFERROR(P27,0))*S27)),0)) -> 0 | R27: =IF(B27="","",IFERROR(G27+IFERROR(J27,0)+IFERROR(M27,0)-IFERROR(P27,0),0)) -> 0 | S27: 0.25 | V27: =IF(B27="","",IFERROR(H27+IFERROR(J27,0)-IFERROR(N27,0),0)) -> 2683.9 | W27: =IF(B27="","",IFERROR(V27-X27,0)) -> 1132.27 | X27: =IF(B27="","",IFERROR(I27+Q27-IFERROR(O27,0),0)) -> 1551.63 | Y27: 2683.9
A28: =IF(AND(B28<>"",G28>0,OR(G28<500,G28<Y28*0.05)),"⚠","") | B28: yt | D28: 65’’ TV TV LED BEKO B65B 880B | E28: "SOLİTON LTD" MƏHDUD MƏSULİYYƏTLİ CƏMİYYƏTİ | F28: 44562 | G28: 565.95 | H28: 1341.52 | I28: 775.57 | M28: =IF(OR(K28="",K28=0),"",IFERROR(MAX(0,K28-L28),0)) | P28: =IF(N28="","",IFERROR(N28-O28,0)) | Q28: =IF(B28="","",IFERROR(IF(U28<>"",U28,IF(T28=1,G28+IFERROR(J28,0)+IFERROR(M28,0)-IFERROR(P28,0),(G28+IFERROR(J28,0)+IFERROR(M28,0)-IFERROR(P28,0))*S28)),0)) -> 0 | R28: =IF(B28="","",IFERROR(G28+IFERROR(J28,0)+IFERROR(M28,0)-IFERROR(P28,0),0)) -> 0 | S28: 0.25 | V28: =IF(B28="","",IFERROR(H28+IFERROR(J28,0)-IFERROR(N28,0),0)) -> 1341.52 | W28: =IF(B28="","",IFERROR(V28-X28,0)) -> 565.95 | X28: =IF(B28="","",IFERROR(I28+Q28-IFERROR(O28,0),0)) -> 775.57 | Y28: 1341.52
A29: =IF(AND(B29<>"",G29>0,OR(G29<500,G29<Y29*0.05)),"⚠","") | B29: yt | D29: IPHONE 13 MINI 128GB BLUE | E29: "SOLİTON LTD" MƏHDUD MƏSULİYYƏTLİ CƏMİYYƏTİ | F29: 44562 | G29: 648.9 | H29: 1538.14 | I29: 889.24 | M29: =IF(OR(K29="",K29=0),"",IFERROR(MAX(0,K29-L29),0)) | P29: =IF(N29="","",IFERROR(N29-O29,0)) | Q29: =IF(B29="","",IFERROR(IF(U29<>"",U29,IF(T29=1,G29+IFERROR(J29,0)+IFERROR(M29,0)-IFERROR(P29,0),(G29+IFERROR(J29,0)+IFERROR(M29,0)-IFERROR(P29,0))*S29)),0)) -> 0 | R29: =IF(B29="","",IFERROR(G29+IFERROR(J29,0)+IFERROR(M29,0)-IFERROR(P29,0),0)) -> 0 | S29: 0.25 | V29: =IF(B29="","",IFERROR(H29+IFERROR(J29,0)-IFERROR(N29,0),0)) -> 1538.14 | W29: =IF(B29="","",IFERROR(V29-X29,0)) -> 648.9 | X29: =IF(B29="","",IFERROR(I29+Q29-IFERROR(O29,0),0)) -> 889.24 | Y29: 1538.14
A30: =IF(AND(B30<>"",G30>0,OR(G30<500,G30<Y30*0.05)),"⚠","") | B30: yt | D30: ThinkPad E15 G2/ 15.6' Full HD/ i7-1165G7/ 16GB/ 512GB SSD/ Free Dos/ 1Y WRTY | E30: "DİVİ CORPORATİON" MƏHDUD MƏSULİYYƏTLİ CƏMİYYƏTİ | F30: 44562 | G30: 779.79375 | H30: 1848.4 | I30: 1068.6063 | M30: =IF(OR(K30="",K30=0),"",IFERROR(MAX(0,K30-L30),0)) | P30: =IF(N30="","",IFERROR(N30-O30,0)) | Q30: =IF(B30="","",IFERROR(IF(U30<>"",U30,IF(T30=1,G30+IFERROR(J30,0)+IFERROR(M30,0)-IFERROR(P30,0),(G30+IFERROR(J30,0)+IFERROR(M30,0)-IFERROR(P30,0))*S30)),0)) -> 0 | R30: =IF(B30="","",IFERROR(G30+IFERROR(J30,0)+IFERROR(M30,0)-IFERROR(P30,0),0)) -> 0 | S30: 0.25 | V30: =IF(B30="","",IFERROR(H30+IFERROR(J30,0)-IFERROR(N30,0),0)) -> 1848.4 | W30: =IF(B30="","",IFERROR(V30-X30,0)) -> 779.79375 | X30: =IF(B30="","",IFERROR(I30+Q30-IFERROR(O30,0),0)) -> 1068.6063 | Y30: 1848.4
A31: =IF(AND(B31<>"",G31>0,OR(G31<500,G31<Y31*0.05)),"⚠","") | B31: yt | D31: ThinkPad E15 G2/ 15.6' Full HD/ i7-1165G7/ 16GB/ 512GB SSD/ Free Dos/ 1Y WRTY | E31: "DİVİ CORPORATİON" MƏHDUD MƏSULİYYƏTLİ CƏMİYYƏTİ | F31: 44562 | G31: 779.79375 | H31: 1848.4 | I31: 1068.6063 | M31: =IF(OR(K31="",K31=0),"",IFERROR(MAX(0,K31-L31),0)) | P31: =IF(N31="","",IFERROR(N31-O31,0)) | Q31: =IF(B31="","",IFERROR(IF(U31<>"",U31,IF(T31=1,G31+IFERROR(J31,0)+IFERROR(M31,0)-IFERROR(P31,0),(G31+IFERROR(J31,0)+IFERROR(M31,0)-IFERROR(P31,0))*S31)),0)) -> 0 | R31: =IF(B31="","",IFERROR(G31+IFERROR(J31,0)+IFERROR(M31,0)-IFERROR(P31,0),0)) -> 0 | S31: 0.25 | V31: =IF(B31="","",IFERROR(H31+IFERROR(J31,0)-IFERROR(N31,0),0)) -> 1848.4 | W31: =IF(B31="","",IFERROR(V31-X31,0)) -> 779.79375 | X31: =IF(B31="","",IFERROR(I31+Q31-IFERROR(O31,0),0)) -> 1068.6063 | Y31: 1848.4
A32: =IF(AND(B32<>"",G32>0,OR(G32<500,G32<Y32*0.05)),"⚠","") | B32: yt | D32: ThinkPad E15 G2/ 15.6' Full HD/ i7-1165G7/ 16GB/ 512GB SSD/ Free Dos/ 1Y WRTY | E32: "DİVİ CORPORATİON" MƏHDUD MƏSULİYYƏTLİ CƏMİYYƏTİ | F32: 44562 | G32: 779.79375 | H32: 1848.4 | I32: 1068.6063 | M32: =IF(OR(K32="",K32=0),"",IFERROR(MAX(0,K32-L32),0)) | P32: =IF(N32="","",IFERROR(N32-O32,0)) | Q32: =IF(B32="","",IFERROR(IF(U32<>"",U32,IF(T32=1,G32+IFERROR(J32,0)+IFERROR(M32,0)-IFERROR(P32,0),(G32+IFERROR(J32,0)+IFERROR(M32,0)-IFERROR(P32,0))*S32)),0)) -> 0 | R32: =IF(B32="","",IFERROR(G32+IFERROR(J32,0)+IFERROR(M32,0)-IFERROR(P32,0),0)) -> 0 | S32: 0.25 | V32: =IF(B32="","",IFERROR(H32+IFERROR(J32,0)-IFERROR(N32,0),0)) -> 1848.4 | W32: =IF(B32="","",IFERROR(V32-X32,0)) -> 779.79375 | X32: =IF(B32="","",IFERROR(I32+Q32-IFERROR(O32,0),0)) -> 1068.6063 | Y32: 1848.4
A33: =IF(AND(B33<>"",G33>0,OR(G33<500,G33<Y33*0.05)),"⚠","") | B33: yt | D33: ThinkPad E15 G2/ 15.6' Full HD/ i7-1165G7/ 16GB/ 512GB SSD/ Free Dos/ 1Y WRTY | E33: "DİVİ CORPORATİON" MƏHDUD MƏSULİYYƏTLİ CƏMİYYƏTİ | F33: 44562 | G33: 779.79375 | H33: 1848.4 | I33: 1068.6063 | M33: =IF(OR(K33="",K33=0),"",IFERROR(MAX(0,K33-L33),0)) | P33: =IF(N33="","",IFERROR(N33-O33,0)) | Q33: =IF(B33="","",IFERROR(IF(U33<>"",U33,IF(T33=1,G33+IFERROR(J33,0)+IFERROR(M33,0)-IFERROR(P33,0),(G33+IFERROR(J33,0)+IFERROR(M33,0)-IFERROR(P33,0))*S33)),0)) -> 0 | R33: =IF(B33="","",IFERROR(G33+IFERROR(J33,0)+IFERROR(M33,0)-IFERROR(P33,0),0)) -> 0 | S33: 0.25 | V33: =IF(B33="","",IFERROR(H33+IFERROR(J33,0)-IFERROR(N33,0),0)) -> 1848.4 | W33: =IF(B33="","",IFERROR(V33-X33,0)) -> 779.79375 | X33: =IF(B33="","",IFERROR(I33+Q33-IFERROR(O33,0),0)) -> 1068.6063 | Y33: 1848.4
A34: =IF(AND(B34<>"",G34>0,OR(G34<500,G34<Y34*0.05)),"⚠","") | B34: yt | D34: ThinkPad E15 G2/ 15.6' Full HD/ i7-1165G7/ 16GB/ 512GB SSD/ Free Dos/ 1Y WRTY | E34: "DİVİ CORPORATİON" MƏHDUD MƏSULİYYƏTLİ CƏMİYYƏTİ | F34: 44562 | G34: 779.79375 | H34: 1848.4 | I34: 1068.6063 | M34: =IF(OR(K34="",K34=0),"",IFERROR(MAX(0,K34-L34),0)) | P34: =IF(N34="","",IFERROR(N34-O34,0)) | Q34: =IF(B34="","",IFERROR(IF(U34<>"",U34,IF(T34=1,G34+IFERROR(J34,0)+IFERROR(M34,0)-IFERROR(P34,0),(G34+IFERROR(J34,0)+IFERROR(M34,0)-IFERROR(P34,0))*S34)),0)) -> 0 | R34: =IF(B34="","",IFERROR(G34+IFERROR(J34,0)+IFERROR(M34,0)-IFERROR(P34,0),0)) -> 0 | S34: 0.25 | V34: =IF(B34="","",IFERROR(H34+IFERROR(J34,0)-IFERROR(N34,0),0)) -> 1848.4 | W34: =IF(B34="","",IFERROR(V34-X34,0)) -> 779.79375 | X34: =IF(B34="","",IFERROR(I34+Q34-IFERROR(O34,0),0)) -> 1068.6063 | Y34: 1848.4
A35: =IF(AND(B35<>"",G35>0,OR(G35<500,G35<Y35*0.05)),"⚠","") | B35: yt | D35: Laptop Lenovo L3 15IML05/ 15.6' FHD IPS/ i7 10510U/ 12GB/ 1TB + 256GB SSD/ NV MX330 2GB/ Free D/Li-P | E35: "DİVİ CORPORATİON" MƏHDUD MƏSULİYYƏTLİ CƏMİYYƏTİ | F35: 44562 | G35: 693.89578 | H35: 1644.79 | I35: 950.89422 | M35: =IF(OR(K35="",K35=0),"",IFERROR(MAX(0,K35-L35),0)) | P35: =IF(N35="","",IFERROR(N35-O35,0)) | Q35: =IF(B35="","",IFERROR(IF(U35<>"",U35,IF(T35=1,G35+IFERROR(J35,0)+IFERROR(M35,0)-IFERROR(P35,0),(G35+IFERROR(J35,0)+IFERROR(M35,0)-IFERROR(P35,0))*S35)),0)) -> 0 | R35: =IF(B35="","",IFERROR(G35+IFERROR(J35,0)+IFERROR(M35,0)-IFERROR(P35,0),0)) -> 0 | S35: 0.25 | V35: =IF(B35="","",IFERROR(H35+IFERROR(J35,0)-IFERROR(N35,0),0)) -> 1644.79 | W35: =IF(B35="","",IFERROR(V35-X35,0)) -> 693.89578 | X35: =IF(B35="","",IFERROR(I35+Q35-IFERROR(O35,0),0)) -> 950.89422 | Y35: 1644.79
A36: =IF(AND(B36<>"",G36>0,OR(G36<500,G36<Y36*0.05)),"⚠","") | B36: yt | D36: Laptop Lenovo L3 15IML05/ 15.6' FHD IPS/ i7 10510U/ 12GB/ 1TB + 256GB SSD/ NV MX330 2GB/ Free D/Li-P | E36: "DİVİ CORPORATİON" MƏHDUD MƏSULİYYƏTLİ CƏMİYYƏTİ | F36: 44562 | G36: 693.89578 | H36: 1644.79 | I36: 950.89422 | M36: =IF(OR(K36="",K36=0),"",IFERROR(MAX(0,K36-L36),0)) | P36: =IF(N36="","",IFERROR(N36-O36,0)) | Q36: =IF(B36="","",IFERROR(IF(U36<>"",U36,IF(T36=1,G36+IFERROR(J36,0)+IFERROR(M36,0)-IFERROR(P36,0),(G36+IFERROR(J36,0)+IFERROR(M36,0)-IFERROR(P36,0))*S36)),0)) -> 0 | R36: =IF(B36="","",IFERROR(G36+IFERROR(J36,0)+IFERROR(M36,0)-IFERROR(P36,0),0)) -> 0 | S36: 0.25 | V36: =IF(B36="","",IFERROR(H36+IFERROR(J36,0)-IFERROR(N36,0),0)) -> 1644.79 | W36: =IF(B36="","",IFERROR(V36-X36,0)) -> 693.89578 | X36: =IF(B36="","",IFERROR(I36+Q36-IFERROR(O36,0),0)) -> 950.89422 | Y36: 1644.79
A37: =IF(AND(B37<>"",G37>0,OR(G37<500,G37<Y37*0.05)),"⚠","") | B37: yt | D37: UniFi 6 Pro (U6-Pro) | E37: "BRAVO TECHNOLOGİES" MƏHDUD MƏSULİYYƏTLİ CƏMİYYƏTİ | F37: 44562 | H37: 590 | I37: 590 | M37: =IF(OR(K37="",K37=0),"",IFERROR(MAX(0,K37-L37),0)) | P37: =IF(N37="","",IFERROR(N37-O37,0)) | Q37: =IF(B37="","",IFERROR(IF(U37<>"",U37,IF(T37=1,G37+IFERROR(J37,0)+IFERROR(M37,0)-IFERROR(P37,0),(G37+IFERROR(J37,0)+IFERROR(M37,0)-IFERROR(P37,0))*S37)),0)) -> 0 | R37: =IF(B37="","",IFERROR(G37+IFERROR(J37,0)+IFERROR(M37,0)-IFERROR(P37,0),0)) -> 0 | S37: 1 | T37: 1 | V37: =IF(B37="","",IFERROR(H37+IFERROR(J37,0)-IFERROR(N37,0),0)) -> 590 | W37: =IF(B37="","",IFERROR(V37-X37,0)) -> 0 | X37: =IF(B37="","",IFERROR(I37+Q37-IFERROR(O37,0),0)) -> 590 | Y37: 590
A38: =IF(AND(B38<>"",G38>0,OR(G38<500,G38<Y38*0.05)),"⚠","") | B38: dg | D38: "X-name" əsas masa yan tumbalı (2000x1660x760) (liyon Valnut/qara) | E38: "TOKEN AZƏRBAYCAN" MƏHDUD MƏSULİYYƏTLİ CƏMİYYƏTİ | F38: 44927 | G38: 660.48 | H38: 1032 | I38: 371.52 | M38: =IF(OR(K38="",K38=0),"",IFERROR(MAX(0,K38-L38),0)) | P38: =IF(N38="","",IFERROR(N38-O38,0)) | Q38: =IF(B38="","",IFERROR(IF(U38<>"",U38,IF(T38=1,G38+IFERROR(J38,0)+IFERROR(M38,0)-IFERROR(P38,0),(G38+IFERROR(J38,0)+IFERROR(M38,0)-IFERROR(P38,0))*S38)),0)) -> 0 | R38: =IF(B38="","",IFERROR(G38+IFERROR(J38,0)+IFERROR(M38,0)-IFERROR(P38,0),0)) -> 0 | S38: 0.2 | V38: =IF(B38="","",IFERROR(H38+IFERROR(J38,0)-IFERROR(N38,0),0)) -> 1032 | W38: =IF(B38="","",IFERROR(V38-X38,0)) -> 660.48 | X38: =IF(B38="","",IFERROR(I38+Q38-IFERROR(O38,0),0)) -> 371.52 | Y38: 1032
A39: =IF(AND(B39<>"",G39>0,OR(G39<500,G39<Y39*0.05)),"⚠","") | B39: yt | D39: iPhone 13 128GB | E39: "ABC-TELECOM" MƏHDUD MƏSULİYYƏTLİ CƏMİYYƏTİ | F39: 44927 | G39: 770.81 | H39: 1370.34 | I39: 599.53 | M39: =IF(OR(K39="",K39=0),"",IFERROR(MAX(0,K39-L39),0)) | P39: =IF(N39="","",IFERROR(N39-O39,0)) | Q39: =IF(B39="","",IFERROR(IF(U39<>"",U39,IF(T39=1,G39+IFERROR(J39,0)+IFERROR(M39,0)-IFERROR(P39,0),(G39+IFERROR(J39,0)+IFERROR(M39,0)-IFERROR(P39,0))*S39)),0)) -> 0 | R39: =IF(B39="","",IFERROR(G39+IFERROR(J39,0)+IFERROR(M39,0)-IFERROR(P39,0),0)) -> 0 | S39: 0.25 | V39: =IF(B39="","",IFERROR(H39+IFERROR(J39,0)-IFERROR(N39,0),0)) -> 1370.34 | W39: =IF(B39="","",IFERROR(V39-X39,0)) -> 770.81 | X39: =IF(B39="","",IFERROR(I39+Q39-IFERROR(O39,0),0)) -> 599.53 | Y39: 1370.34
A40: =IF(AND(B40<>"",G40>0,OR(G40<500,G40<Y40*0.05)),"⚠","") | B40: yt | D40: Laptop Lenovo ThinkPad T14 G3 | E40: "DİVİ CORPORATİON" MƏHDUD MƏSULİYYƏTLİ CƏMİYYƏTİ | F40: 44927 | G40: 1520.6 | H40: 2703.29 | I40: 1182.69 | M40: =IF(OR(K40="",K40=0),"",IFERROR(MAX(0,K40-L40),0)) | P40: =IF(N40="","",IFERROR(N40-O40,0)) | Q40: =IF(B40="","",IFERROR(IF(U40<>"",U40,IF(T40=1,G40+IFERROR(J40,0)+IFERROR(M40,0)-IFERROR(P40,0),(G40+IFERROR(J40,0)+IFERROR(M40,0)-IFERROR(P40,0))*S40)),0)) -> 0 | R40: =IF(B40="","",IFERROR(G40+IFERROR(J40,0)+IFERROR(M40,0)-IFERROR(P40,0),0)) -> 0 | S40: 0.25 | V40: =IF(B40="","",IFERROR(H40+IFERROR(J40,0)-IFERROR(N40,0),0)) -> 2703.29 | W40: =IF(B40="","",IFERROR(V40-X40,0)) -> 1520.6 | X40: =IF(B40="","",IFERROR(I40+Q40-IFERROR(O40,0),0)) -> 1182.69 | Y40: 2703.29
A41: =IF(AND(B41<>"",G41>0,OR(G41<500,G41<Y41*0.05)),"⚠","") | B41: yt | D41: Lenovo ThinkBook 15 G4 IAP | E41: "DİVİ CORPORATİON" MƏHDUD MƏSULİYYƏTLİ CƏMİYYƏTİ | F41: 44927 | G41: 973.93 | H41: 1731.44 | I41: 757.51 | M41: =IF(OR(K41="",K41=0),"",IFERROR(MAX(0,K41-L41),0)) | P41: =IF(N41="","",IFERROR(N41-O41,0)) | Q41: =IF(B41="","",IFERROR(IF(U41<>"",U41,IF(T41=1,G41+IFERROR(J41,0)+IFERROR(M41,0)-IFERROR(P41,0),(G41+IFERROR(J41,0)+IFERROR(M41,0)-IFERROR(P41,0))*S41)),0)) -> 0 | R41: =IF(B41="","",IFERROR(G41+IFERROR(J41,0)+IFERROR(M41,0)-IFERROR(P41,0),0)) -> 0 | S41: 0.25 | V41: =IF(B41="","",IFERROR(H41+IFERROR(J41,0)-IFERROR(N41,0),0)) -> 1731.44 | W41: =IF(B41="","",IFERROR(V41-X41,0)) -> 973.93 | X41: =IF(B41="","",IFERROR(I41+Q41-IFERROR(O41,0),0)) -> 757.51 | Y41: 1731.44
...

Sheet QMA
A1: QEYRİ-MADDİ AKTİVLƏR — Amortizasiya Cədvəli | VM AZ Maddə 114
A2: İdentifikasiya | D2: İlin əvvəlinə | F2: Daxilolmalar | H2: Xaricetmə | J2: Amortizasiya | M2: İlin sonuna
A3: Kod | B3: Adı | C3: Növü | D3: İlkin dəyər (il əvvəli) | E3: Yığılmış (il əvvəli) | F3: Daxilolma İlkin dəyər | G3: FİM (il) | H3: Xaric İlkin | I3: Xaric Yığılmış | J3: Hesab. Amort. | M3: İlkin dəyər (il sonu) | N3: Qalıq dəyər (il sonu) | O3: Yığılmış (il sonu)
A4: C Ə M İ | D4: =IFERROR(SUM(D6:D505),0) -> 4384.59 | E4: =IFERROR(SUM(E6:E505),0) -> 447.534 | J4: =IFERROR(SUM(J6:J505),0) -> 438.459 | M4: =IFERROR(SUM(M6:M505),0) -> 4384.59 | N4: =IFERROR(SUM(N6:N505),0) -> 3498.597 | O4: =IFERROR(SUM(O6:O505),0) -> 885.993
A6: qma-n | B6: Windows 10 | C6: qma-n | D6: 288.81 | E6: 54.87 | J6: =IF(A6="","",IFERROR(IF(L6<>"",L6,IF(C6="qma-m",IF(G6>0,MIN((D6+IFERROR(F6,0))*(1/G6),(D6+IFERROR(F6,0))-(E6-IFERROR(I6,0))),0),MIN((D6+IFERROR(F6,0))*0.1,(D6+IFERROR(F6,0))-(E6-IFERROR(I6,0))))),0)) -> 28.881 | M6: =IF(A6="","",IFERROR(D6+IFERROR(F6,0)-IFERROR(H6,0),0)) -> 288.81 | N6: =IF(A6="","",IFERROR(M6-O6,0)) -> 205.059 | O6: =IF(A6="","",IFERROR(E6+J6-IFERROR(I6,0),0)) -> 83.751
A7: qma-n | B7: Windows 10 | C7: qma-n | D7: 288.81 | E7: 54.87 | J7: =IF(A7="","",IFERROR(IF(L7<>"",L7,IF(C7="qma-m",IF(G7>0,MIN((D7+IFERROR(F7,0))*(1/G7),(D7+IFERROR(F7,0))-(E7-IFERROR(I7,0))),0),MIN((D7+IFERROR(F7,0))*0.1,(D7+IFERROR(F7,0))-(E7-IFERROR(I7,0))))),0)) -> 28.881 | M7: =IF(A7="","",IFERROR(D7+IFERROR(F7,0)-IFERROR(H7,0),0)) -> 288.81 | N7: =IF(A7="","",IFERROR(M7-O7,0)) -> 205.059 | O7: =IF(A7="","",IFERROR(E7+J7-IFERROR(I7,0),0)) -> 83.751
A8: qma-n | B8: Windows 10 | C8: qma-n | D8: 288.81 | E8: 54.87 | J8: =IF(A8="","",IFERROR(IF(L8<>"",L8,IF(C8="qma-m",IF(G8>0,MIN((D8+IFERROR(F8,0))*(1/G8),(D8+IFERROR(F8,0))-(E8-IFERROR(I8,0))),0),MIN((D8+IFERROR(F8,0))*0.1,(D8+IFERROR(F8,0))-(E8-IFERROR(I8,0))))),0)) -> 28.881 | M8: =IF(A8="","",IFERROR(D8+IFERROR(F8,0)-IFERROR(H8,0),0)) -> 288.81 | N8: =IF(A8="","",IFERROR(M8-O8,0)) -> 205.059 | O8: =IF(A8="","",IFERROR(E8+J8-IFERROR(I8,0),0)) -> 83.751
A9: qma-n | B9: Windows 10 | C9: qma-n | D9: 288.81 | E9: 54.87 | J9: =IF(A9="","",IFERROR(IF(L9<>"",L9,IF(C9="qma-m",IF(G9>0,MIN((D9+IFERROR(F9,0))*(1/G9),(D9+IFERROR(F9,0))-(E9-IFERROR(I9,0))),0),MIN((D9+IFERROR(F9,0))*0.1,(D9+IFERROR(F9,0))-(E9-IFERROR(I9,0))))),0)) -> 28.881 | M9: =IF(A9="","",IFERROR(D9+IFERROR(F9,0)-IFERROR(H9,0),0)) -> 288.81 | N9: =IF(A9="","",IFERROR(M9-O9,0)) -> 205.059 | O9: =IF(A9="","",IFERROR(E9+J9-IFERROR(I9,0),0)) -> 83.751
A10: qma-n | B10: Windows 10 | C10: qma-n | D10: 288.81 | E10: 54.87 | J10: =IF(A10="","",IFERROR(IF(L10<>"",L10,IF(C10="qma-m",IF(G10>0,MIN((D10+IFERROR(F10,0))*(1/G10),(D10+IFERROR(F10,0))-(E10-IFERROR(I10,0))),0),MIN((D10+IFERROR(F10,0))*0.1,(D10+IFERROR(F10,0))-(E10-IFERROR(I10,0))))),0)) -> 28.881 | M10: =IF(A10="","",IFERROR(D10+IFERROR(F10,0)-IFERROR(H10,0),0)) -> 288.81 | N10: =IF(A10="","",IFERROR(M10-O10,0)) -> 205.059 | O10: =IF(A10="","",IFERROR(E10+J10-IFERROR(I10,0),0)) -> 83.751
A11: qma-n | B11: Windows 11 | C11: qma-n | D11: 288.47 | E11: 28.847 | J11: =IF(A11="","",IFERROR(IF(L11<>"",L11,IF(C11="qma-m",IF(G11>0,MIN((D11+IFERROR(F11,0))*(1/G11),(D11+IFERROR(F11,0))-(E11-IFERROR(I11,0))),0),MIN((D11+IFERROR(F11,0))*0.1,(D11+IFERROR(F11,0))-(E11-IFERROR(I11,0))))),0)) -> 28.847 | M11: =IF(A11="","",IFERROR(D11+IFERROR(F11,0)-IFERROR(H11,0),0)) -> 288.47 | N11: =IF(A11="","",IFERROR(M11-O11,0)) -> 230.776 | O11: =IF(A11="","",IFERROR(E11+J11-IFERROR(I11,0),0)) -> 57.694
A12: qma-n | B12: Windows 11 | C12: qma-n | D12: 288.47 | E12: 28.847 | J12: =IF(A12="","",IFERROR(IF(L12<>"",L12,IF(C12="qma-m",IF(G12>0,MIN((D12+IFERROR(F12,0))*(1/G12),(D12+IFERROR(F12,0))-(E12-IFERROR(I12,0))),0),MIN((D12+IFERROR(F12,0))*0.1,(D12+IFERROR(F12,0))-(E12-IFERROR(I12,0))))),0)) -> 28.847 | M12: =IF(A12="","",IFERROR(D12+IFERROR(F12,0)-IFERROR(H12,0),0)) -> 288.47 | N12: =IF(A12="","",IFERROR(M12-O12,0)) -> 230.776 | O12: =IF(A12="","",IFERROR(E12+J12-IFERROR(I12,0),0)) -> 57.694
A13: qma-n | B13: Windows 10 | C13: qma-n | D13: 288.81 | E13: 28.881 | J13: =IF(A13="","",IFERROR(IF(L13<>"",L13,IF(C13="qma-m",IF(G13>0,MIN((D13+IFERROR(F13,0))*(1/G13),(D13+IFERROR(F13,0))-(E13-IFERROR(I13,0))),0),MIN((D13+IFERROR(F13,0))*0.1,(D13+IFERROR(F13,0))-(E13-IFERROR(I13,0))))),0)) -> 28.881 | M13: =IF(A13="","",IFERROR(D13+IFERROR(F13,0)-IFERROR(H13,0),0)) -> 288.81 | N13: =IF(A13="","",IFERROR(M13-O13,0)) -> 231.048 | O13: =IF(A13="","",IFERROR(E13+J13-IFERROR(I13,0),0)) -> 57.762
A14: qma-n | B14: Windows 10 | C14: qma-n | D14: 288.81 | E14: 28.881 | J14: =IF(A14="","",IFERROR(IF(L14<>"",L14,IF(C14="qma-m",IF(G14>0,MIN((D14+IFERROR(F14,0))*(1/G14),(D14+IFERROR(F14,0))-(E14-IFERROR(I14,0))),0),MIN((D14+IFERROR(F14,0))*0.1,(D14+IFERROR(F14,0))-(E14-IFERROR(I14,0))))),0)) -> 28.881 | M14: =IF(A14="","",IFERROR(D14+IFERROR(F14,0)-IFERROR(H14,0),0)) -> 288.81 | N14: =IF(A14="","",IFERROR(M14-O14,0)) -> 231.048 | O14: =IF(A14="","",IFERROR(E14+J14-IFERROR(I14,0),0)) -> 57.762
A15: qma-n | B15: Windows 10 | C15: qma-n | D15: 288.81 | E15: 28.881 | J15: =IF(A15="","",IFERROR(IF(L15<>"",L15,IF(C15="qma-m",IF(G15>0,MIN((D15+IFERROR(F15,0))*(1/G15),(D15+IFERROR(F15,0))-(E15-IFERROR(I15,0))),0),MIN((D15+IFERROR(F15,0))*0.1,(D15+IFERROR(F15,0))-(E15-IFERROR(I15,0))))),0)) -> 28.881 | M15: =IF(A15="","",IFERROR(D15+IFERROR(F15,0)-IFERROR(H15,0),0)) -> 288.81 | N15: =IF(A15="","",IFERROR(M15-O15,0)) -> 231.048 | O15: =IF(A15="","",IFERROR(E15+J15-IFERROR(I15,0),0)) -> 57.762
A16: qma-n | B16: Windows 10 | C16: qma-n | D16: 288.47 | E16: 28.847 | J16: =IF(A16="","",IFERROR(IF(L16<>"",L16,IF(C16="qma-m",IF(G16>0,MIN((D16+IFERROR(F16,0))*(1/G16),(D16+IFERROR(F16,0))-(E16-IFERROR(I16,0))),0),MIN((D16+IFERROR(F16,0))*0.1,(D16+IFERROR(F16,0))-(E16-IFERROR(I16,0))))),0)) -> 28.847 | M16: =IF(A16="","",IFERROR(D16+IFERROR(F16,0)-IFERROR(H16,0),0)) -> 288.47 | N16: =IF(A16="","",IFERROR(M16-O16,0)) -> 230.776 | O16: =IF(A16="","",IFERROR(E16+J16-IFERROR(I16,0),0)) -> 57.694
A17: qma-n | B17: Windows 11 | C17: qma-n | D17: 302.89 | J17: =IF(A17="","",IFERROR(IF(L17<>"",L17,IF(C17="qma-m",IF(G17>0,MIN((D17+IFERROR(F17,0))*(1/G17),(D17+IFERROR(F17,0))-(E17-IFERROR(I17,0))),0),MIN((D17+IFERROR(F17,0))*0.1,(D17+IFERROR(F17,0))-(E17-IFERROR(I17,0))))),0)) -> 30.289 | M17: =IF(A17="","",IFERROR(D17+IFERROR(F17,0)-IFERROR(H17,0),0)) -> 302.89 | N17: =IF(A17="","",IFERROR(M17-O17,0)) -> 272.601 | O17: =IF(A17="","",IFERROR(E17+J17-IFERROR(I17,0),0)) -> 30.289
A18: qma-n | B18: Windows 11 | C18: qma-n | D18: 298.57 | J18: =IF(A18="","",IFERROR(IF(L18<>"",L18,IF(C18="qma-m",IF(G18>0,MIN((D18+IFERROR(F18,0))*(1/G18),(D18+IFERROR(F18,0))-(E18-IFERROR(I18,0))),0),MIN((D18+IFERROR(F18,0))*0.1,(D18+IFERROR(F18,0))-(E18-IFERROR(I18,0))))),0)) -> 29.857 | M18: =IF(A18="","",IFERROR(D18+IFERROR(F18,0)-IFERROR(H18,0),0)) -> 298.57 | N18: =IF(A18="","",IFERROR(M18-O18,0)) -> 268.713 | O18: =IF(A18="","",IFERROR(E18+J18-IFERROR(I18,0),0)) -> 29.857
A19: qma-n | B19: Windows 11 | C19: qma-n | D19: 298.57 | J19: =IF(A19="","",IFERROR(IF(L19<>"",L19,IF(C19="qma-m",IF(G19>0,MIN((D19+IFERROR(F19,0))*(1/G19),(D19+IFERROR(F19,0))-(E19-IFERROR(I19,0))),0),MIN((D19+IFERROR(F19,0))*0.1,(D19+IFERROR(F19,0))-(E19-IFERROR(I19,0))))),0)) -> 29.857 | M19: =IF(A19="","",IFERROR(D19+IFERROR(F19,0)-IFERROR(H19,0),0)) -> 298.57 | N19: =IF(A19="","",IFERROR(M19-O19,0)) -> 268.713 | O19: =IF(A19="","",IFERROR(E19+J19-IFERROR(I19,0),0)) -> 29.857
A20: qma-n | B20: Windows 11 | C20: qma-n | D20: 308.67 | J20: =IF(A20="","",IFERROR(IF(L20<>"",L20,IF(C20="qma-m",IF(G20>0,MIN((D20+IFERROR(F20,0))*(1/G20),(D20+IFERROR(F20,0))-(E20-IFERROR(I20,0))),0),MIN((D20+IFERROR(F20,0))*0.1,(D20+IFERROR(F20,0))-(E20-IFERROR(I20,0))))),0)) -> 30.867 | M20: =IF(A20="","",IFERROR(D20+IFERROR(F20,0)-IFERROR(H20,0),0)) -> 308.67 | N20: =IF(A20="","",IFERROR(M20-O20,0)) -> 277.803 | O20: =IF(A20="","",IFERROR(E20+J20-IFERROR(I20,0),0)) -> 30.867

Sheet parametr
A1: PARAMETRLƏR | Amortizasiya dərəcələri və limitlər
A3: Kod | B3: Kateqoriya | C3: Amort. dərəcə (maks) | D3: Təmir limiti % | E3: Sahibkarlıq meyarı | F3: Qeyd
A4: bt | B4: Binalar, tikililər | C4: 0.07 | D4: 0.02 | E4: 1 | F4: Maks 7%
A5: ma | B5: Maşınlar, avadanlıq | C5: 0.2 | D5: 0.05 | E5: 1 | F5: Maks 20%
A6: nv | B6: Nəqliyyat vasitələri | C6: 0.25 | D6: 0.03 | E6: 1 | F6: Maks 25%
A7: ym | B7: Yük maşınları | C7: 0.25 | D7: 0.08 | E7: 1 | F7: Maks 25%
A8: yt | B8: Yüksək texnologiya | C8: 0.25 | D8: 0.03 | E8: 1 | F8: Maks 25%
A9: dg | B9: Digər əsas vəsaitlər | C9: 0.2 | D9: 0.03 | E9: 1 | F9: Maks 20%
A10: it | B10: İcarəyə götürülmüş ƏV-in təmiri | D10: 0.03 | E10: 1 | F10: 1/MAX(FİM;5)
A11: qma-m | B11: QMA — FİM məlum | F11: 1/FİM
A12: qma-n | B12: QMA — FİM nəməlum | C12: 0.1 | F12: 10% sabit
A15: Sahibkarlıq koefficientləri (amortizasiyaya tətbiq olunur):
A16: Mikro sahibkar | B16: 2 | C16: ← Bas listindən seçilir
A17: Kiçik sahibkar | B17: 1.5 | C17: ← Bas listindən seçilir
A18: Orta sahibkar | B18: 1 | C18: ← Bas listindən seçilir

Sheet Təmir Fondu
A1: TƏMİR XƏRCLƏRİNİN VERGİ FONDU — VM AZ Maddə 115
A3: Kod | B3: Kateqoriya | C3: Qalıq (il əvvəli) | D3: Limit % | E3: Limit (AZN) | F3: Faktiki təmir | G3: Gəlirdən çıxılan | H3: Kapitallaşan
A4: bt | B4: Binalar, tikililər | C4: =IFERROR(SUMIF(EV!B:B,"bt",EV!G:G),0) -> 38447.54 | D4: 0.02 | E4: =IFERROR(C4*D4,0) -> 768.9508 | G4: =IF(F4="","",IFERROR(MIN(E4,F4),0)) | H4: =IF(F4="","",IFERROR(MAX(0,F4-E4),0))
A5: ma | B5: Maşınlar, avadanlıq | C5: =IFERROR(SUMIF(EV!B:B,"ma",EV!G:G),0) -> 0 | D5: 0.05 | E5: =IFERROR(C5*D5,0) -> 0 | G5: =IF(F5="","",IFERROR(MIN(E5,F5),0)) | H5: =IF(F5="","",IFERROR(MAX(0,F5-E5),0))
A6: nv | B6: Nəqliyyat vasitələri | C6: =IFERROR(SUMIF(EV!B:B,"nv",EV!G:G),0) -> 0 | D6: 0.03 | E6: =IFERROR(C6*D6,0) -> 0 | G6: =IF(F6="","",IFERROR(MIN(E6,F6),0)) | H6: =IF(F6="","",IFERROR(MAX(0,F6-E6),0))
A7: ym | B7: Yük maşınları | C7: =IFERROR(SUMIF(EV!B:B,"ym",EV!G:G),0) -> 0 | D7: 0.08 | E7: =IFERROR(C7*D7,0) -> 0 | G7: =IF(F7="","",IFERROR(MIN(E7,F7),0)) | H7: =IF(F7="","",IFERROR(MAX(0,F7-E7),0))
A8: yt | B8: Yüksək texnologiya | C8: =IFERROR(SUMIF(EV!B:B,"yt",EV!G:G),0) -> 70972.117 | D8: 0.03 | E8: =IFERROR(C8*D8,0) -> 2129.1635 | G8: =IF(F8="","",IFERROR(MIN(E8,F8),0)) | H8: =IF(F8="","",IFERROR(MAX(0,F8-E8),0))
A9: dg | B9: Digər əsas vəsaitlər | C9: =IFERROR(SUMIF(EV!B:B,"dg",EV!G:G),0) -> 11260.879 | D9: 0.03 | E9: =IFERROR(C9*D9,0) -> 337.82638 | G9: =IF(F9="","",IFERROR(MIN(E9,F9),0)) | H9: =IF(F9="","",IFERROR(MAX(0,F9-E9),0))
A10: it | B10: İcarə ƏV-nin təmiri | C10: =IFERROR(SUMIF(EV!B:B,"it",EV!G:G),0) -> 0 | D10: 0.03 | E10: =IFERROR(C10*D10,0) -> 0 | G10: =IF(F10="","",IFERROR(MIN(E10,F10),0)) | H10: =IF(F10="","",IFERROR(MAX(0,F10-E10),0))
A11: CƏMI | C11: =IFERROR(SUM(C4:C10),0) -> 120680.54 | E11: =IFERROR(SUM(E4:E10),0) -> 3235.9407 | F11: =IFERROR(SUM(F4:F10),0) -> 0 | G11: =IFERROR(SUM(G4:G10),0) -> 0 | H11: =IFERROR(SUM(H4:H10),0) -> 0
